2021-10-20 04:51:03,816 INFO    MainThread:16020 [internal.py:wandb_internal():88] W&B internal server running at pid: 16020, started at: 2021-10-20 04:51:03.816221
2021-10-20 04:51:03,817 INFO    WriterThread:16020 [datastore.py:open_for_write():77] open: C:\Users\vikram\mlops_vikram\wandb logging\wandb\run-20211020_045102-1a3merzo\run-1a3merzo.wandb
2021-10-20 04:51:03,818 DEBUG   HandlerThread:16020 [handler.py:handle_request():130] handle_request: check_version
2021-10-20 04:51:03,820 DEBUG   SenderThread:16020 [sender.py:send():185] send: header
2021-10-20 04:51:03,820 DEBUG   SenderThread:16020 [sender.py:send_request():199] send_request: check_version
2021-10-20 04:51:03,968 DEBUG   SenderThread:16020 [sender.py:send():185] send: run
2021-10-20 04:51:03,970 INFO    SenderThread:16020 [sender.py:_maybe_setup_resume():450] checking resume status for raviraja/MLOps Basics/1a3merzo
2021-10-20 04:51:04,711 ERROR   SenderThread:16020 [internal_api.py:execute():144] 404 response executing GraphQL.
2021-10-20 04:51:04,711 ERROR   SenderThread:16020 [internal_api.py:execute():145] {"errors":[{"message":"project not found","path":["upsertBucket"]}],"data":{"upsertBucket":null}}
2021-10-20 04:51:04,972 INFO    WriterThread:16020 [datastore.py:close():281] close: C:\Users\vikram\mlops_vikram\wandb logging\wandb\run-20211020_045102-1a3merzo\run-1a3merzo.wandb
2021-10-20 04:51:04,972 INFO    HandlerThread:16020 [handler.py:finish():731] shutting down handler
2021-10-20 04:51:04,972 ERROR   MainThread:16020 [internal.py:wandb_internal():159] Thread SenderThread:
Traceback (most recent call last):
  File "C:\Users\vikram\anaconda3\envs\project-setup\lib\site-packages\wandb\sdk\lib\retry.py", line 102, in __call__
    result = self._call_fn(*args, **kwargs)
  File "C:\Users\vikram\anaconda3\envs\project-setup\lib\site-packages\wandb\sdk\internal\internal_api.py", line 147, in execute
    six.reraise(*sys.exc_info())
  File "C:\Users\vikram\anaconda3\envs\project-setup\lib\site-packages\six.py", line 719, in reraise
    raise value
  File "C:\Users\vikram\anaconda3\envs\project-setup\lib\site-packages\wandb\sdk\internal\internal_api.py", line 141, in execute
    return self.client.execute(*args, **kwargs)
  File "C:\Users\vikram\anaconda3\envs\project-setup\lib\site-packages\wandb\vendor\gql-0.2.0\gql\client.py", line 52, in execute
    result = self._get_result(document, *args, **kwargs)
  File "C:\Users\vikram\anaconda3\envs\project-setup\lib\site-packages\wandb\vendor\gql-0.2.0\gql\client.py", line 60, in _get_result
    return self.transport.execute(document, *args, **kwargs)
  File "C:\Users\vikram\anaconda3\envs\project-setup\lib\site-packages\wandb\vendor\gql-0.2.0\gql\transport\requests.py", line 39, in execute
    request.raise_for_status()
  File "C:\Users\vikram\anaconda3\envs\project-setup\lib\site-packages\requests\models.py", line 953, in raise_for_status
    raise HTTPError(http_error_msg, response=self)
requests.exceptions.HTTPError: 404 Client Error: Not Found for url: https://api.wandb.ai/graphql

During handling of the above exception, another exception occurred:

Traceback (most recent call last):
  File "C:\Users\vikram\anaconda3\envs\project-setup\lib\site-packages\wandb\apis\normalize.py", line 24, in wrapper
    return func(*args, **kwargs)
  File "C:\Users\vikram\anaconda3\envs\project-setup\lib\site-packages\wandb\sdk\internal\internal_api.py", line 1270, in upsert_run
    response = self.gql(mutation, variable_values=variable_values, **kwargs)
  File "C:\Users\vikram\anaconda3\envs\project-setup\lib\site-packages\wandb\sdk\lib\retry.py", line 118, in __call__
    if not check_retry_fn(e):
  File "C:\Users\vikram\anaconda3\envs\project-setup\lib\site-packages\wandb\util.py", line 821, in no_retry_auth
    raise CommError("Permission denied, ask the project owner to grant you access")
wandb.errors.CommError: Permission denied, ask the project owner to grant you access

During handling of the above exception, another exception occurred:

Traceback (most recent call last):
  File "C:\Users\vikram\anaconda3\envs\project-setup\lib\site-packages\wandb\sdk\internal\internal_util.py", line 52, in run
    self._run()
  File "C:\Users\vikram\anaconda3\envs\project-setup\lib\site-packages\wandb\sdk\internal\internal_util.py", line 102, in _run
    self._process(record)
  File "C:\Users\vikram\anaconda3\envs\project-setup\lib\site-packages\wandb\sdk\internal\internal.py", line 292, in _process
    self._sm.send(record)
  File "C:\Users\vikram\anaconda3\envs\project-setup\lib\site-packages\wandb\sdk\internal\sender.py", line 187, in send
    send_handler(record)
  File "C:\Users\vikram\anaconda3\envs\project-setup\lib\site-packages\wandb\sdk\internal\sender.py", line 652, in send_run
    self._init_run(run, config_value_dict)
  File "C:\Users\vikram\anaconda3\envs\project-setup\lib\site-packages\wandb\sdk\internal\sender.py", line 673, in _init_run
    server_run, inserted = self._api.upsert_run(
  File "C:\Users\vikram\anaconda3\envs\project-setup\lib\site-packages\wandb\apis\normalize.py", line 62, in wrapper
    six.reraise(CommError, CommError(message, err), sys.exc_info()[2])
  File "C:\Users\vikram\anaconda3\envs\project-setup\lib\site-packages\six.py", line 718, in reraise
    raise value.with_traceback(tb)
  File "C:\Users\vikram\anaconda3\envs\project-setup\lib\site-packages\wandb\apis\normalize.py", line 24, in wrapper
    return func(*args, **kwargs)
  File "C:\Users\vikram\anaconda3\envs\project-setup\lib\site-packages\wandb\sdk\internal\internal_api.py", line 1270, in upsert_run
    response = self.gql(mutation, variable_values=variable_values, **kwargs)
  File "C:\Users\vikram\anaconda3\envs\project-setup\lib\site-packages\wandb\sdk\lib\retry.py", line 118, in __call__
    if not check_retry_fn(e):
  File "C:\Users\vikram\anaconda3\envs\project-setup\lib\site-packages\wandb\util.py", line 821, in no_retry_auth
    raise CommError("Permission denied, ask the project owner to grant you access")
wandb.errors.CommError: Permission denied, ask the project owner to grant you access
2021-10-20 04:51:07,014 INFO    MainThread:16020 [internal.py:handle_exit():78] Internal process exited
